<?xml version="1.0" ?>
<!-- =================================================================================== -->
<!-- |    This document was autogenerated by xacro from /home/gauss/projects/personal_ws/src/kuka_structure/kuka_structure_description/urdf/kuka_structure_pybullet.xacro | -->
<!-- |    EDITING THIS FILE BY HAND IS NOT RECOMMENDED                                 | -->
<!-- =================================================================================== -->
<!-- It is required to pass the args: robot_name-->
<robot name="kuka_structure">
  <!--  100°/s -->
  <link name="base_link">
    <inertial>
      <origin rpy="0 0 0" xyz="0.035817 -0.1978 -1.2121E-05"/>
      <mass value="780.97"/>
      <inertia ixx="25.789" ixy="-0.0076742" ixz="0.0023584" iyy="48.078" iyz="2.5193E-05" izz="33.648"/>
    </inertial>
    <visual>
      <origin rpy="0 0 0" xyz="0 0 0"/>
      <geometry>
        <mesh filename="package://kuka_structure_description/meshes/base_link.STL" scale="0.001 0.001 0.001"/>
      </geometry>
      <material name="">
        <color rgba="1 0 0 1"/>
      </material>
    </visual>
    <collision>
      <origin rpy="0 0 0" xyz="0 0 0"/>
      <geometry>
        <mesh filename="package://kuka_structure_description/meshes/base_link.STL" scale="0.001 0.001 0.001"/>
      </geometry>
    </collision>
  </link>
  <link name="link_1">
    <inertial>
      <origin rpy="0 0 0" xyz="-0.28012 0.38938 0.024882"/>
      <mass value="660.35"/>
      <inertia ixx="38.274" ixy="9.9756" ixz="-0.5181" iyy="36.77" iyz="0.16531" izz="32.584"/>
    </inertial>
    <visual>
      <origin rpy="0 0 0" xyz="0 0 0"/>
      <geometry>
        <mesh filename="package://kuka_structure_description/meshes/link_1.STL" scale="0.001 0.001 0.001"/>
      </geometry>
      <material name="">
        <color rgba="1 0 0 1"/>
      </material>
    </visual>
    <collision>
      <origin rpy="0 0 0" xyz="0 0 0"/>
      <geometry>
        <mesh filename="package://kuka_structure_description/meshes/link_1.STL" scale="0.001 0.001 0.001"/>
      </geometry>
    </collision>
  </link>
  <joint name="joint_1" type="prismatic">
    <origin rpy="0 0 0" xyz="2.750 0.215 2.720"/>
    <parent link="base_link"/>
    <child link="link_1"/>
    <axis xyz="-1 0 0"/>
    <limit effort="100000" lower="0" upper="3.0" velocity="1.74533"/>
  </joint>
  <transmission name="tran_1">
    <type>transmission_interface/SimpleTransmission</type>
    <joint name="joint_1">
      <hardwareInterface>hardware_interface/EffortJointInterface</hardwareInterface>
    </joint>
    <actuator name="motor_1">
      <mechanicalReduction>1</mechanicalReduction>
    </actuator>
  </transmission>
</robot>

